Workbook

Sheet 考勤记录
A1: 考勤异常报表
A2: 人员姓名 | B2: 所属群组 | C2: 日 期 | D2: 星期 | E2: 班次名称 | F2: 上班刷卡 | G2: 打卡状态 | H2: 下班刷卡 | I2: 打卡状态 | J2: 备注
A3: 何威迪 | B3: 副总经理兼海外气表产品规划管理部及多元智能产品规划管理部产品总监 | C3: 45689 | D3: 星期六 | E3: 休息
A4: 何威迪 | B4: 副总经理兼海外气表产品规划管理部及多元智能产品规划管理部产品总监 | C4: 45690 | D4: 星期日 | E4: 休息
A5: 何威迪 | B5: 副总经理兼海外气表产品规划管理部及多元智能产品规划管理部产品总监 | C5: 45691 | D5: 星期一 | E5: 休息
A6: 何威迪 | B6: 副总经理兼海外气表产品规划管理部及多元智能产品规划管理部产品总监 | C6: 45692 | D6: 星期二 | E6: 休息
A7: 何威迪 | B7: 副总经理兼海外气表产品规划管理部及多元智能产品规划管理部产品总监 | C7: 45693 | D7: 星期三 | E7: 工作日 | F7: 08:32 | G7: 正常 | H7: 19:03 | I7: 正常
A8: 何威迪 | B8: 副总经理兼海外气表产品规划管理部及多元智能产品规划管理部产品总监 | C8: 45694 | D8: 星期四 | E8: 工作日 | F8: 08:32 | G8: 正常 | H8: 20:17 | I8: 正常
A9: 何威迪 | B9: 副总经理兼海外气表产品规划管理部及多元智能产品规划管理部产品总监 | C9: 45695 | D9: 星期五 | E9: 工作日 | F9: 08:32 | G9: 正常 | H9: 18:22 | I9: 正常
A10: 何威迪 | B10: 副总经理兼海外气表产品规划管理部及多元智能产品规划管理部产品总监 | C10: 45696 | D10: 星期六 | E10: 工作日 | F10: 08:25 | G10: 正常 | H10: 18:45 | I10: 正常
A11: 何威迪 | B11: 副总经理兼海外气表产品规划管理部及多元智能产品规划管理部产品总监 | C11: 45697 | D11: 星期日 | E11: 休息
A12: 何威迪 | B12: 副总经理兼海外气表产品规划管理部及多元智能产品规划管理部产品总监 | C12: 45698 | D12: 星期一 | E12: 工作日 | F12: 08:26 | G12: 正常 | H12: 20:11 | I12: 正常
A13: 何威迪 | B13: 副总经理兼海外气表产品规划管理部及多元智能产品规划管理部产品总监 | C13: 45699 | D13: 星期二 | E13: 工作日 | F13: 08:26 | G13: 正常 | H13: 18:36 | I13: 正常
A14: 何威迪 | B14: 副总经理兼海外气表产品规划管理部及多元智能产品规划管理部产品总监 | C14: 45700 | D14: 星期三 | E14: 工作日 | F14: 08:28 | G14: 正常 | H14: 18:23 | I14: 正常
A15: 何威迪 | B15: 副总经理兼海外气表产品规划管理部及多元智能产品规划管理部产品总监 | C15: 45701 | D15: 星期四 | E15: 工作日 | F15: 08:28 | G15: 正常 | H15: 20:05 | I15: 正常
A16: 何威迪 | B16: 副总经理兼海外气表产品规划管理部及多元智能产品规划管理部产品总监 | C16: 45702 | D16: 星期五 | E16: 工作日 | F16: 08:30 | G16: 正常 | H16: 18:35 | I16: 正常
A17: 何威迪 | B17: 副总经理兼海外气表产品规划管理部及多元智能产品规划管理部产品总监 | C17: 45703 | D17: 星期六 | E17: 休息 | F17: 08:45 | G17: 正常 | H17: 16:26 | I17: 正常
A18: 何威迪 | B18: 副总经理兼海外气表产品规划管理部及多元智能产品规划管理部产品总监 | C18: 45704 | D18: 星期日 | E18: 休息
A19: 何威迪 | B19: 副总经理兼海外气表产品规划管理部及多元智能产品规划管理部产品总监 | C19: 45705 | D19: 星期一 | E19: 工作日 | F19: 08:19 | G19: 正常 | H19: 20:10 | I19: 正常
A20: 何威迪 | B20: 副总经理兼海外气表产品规划管理部及多元智能产品规划管理部产品总监 | C20: 45706 | D20: 星期二 | E20: 工作日 | F20: 08:30 | G20: 正常 | H20: 18:13 | I20: 正常
A21: 何威迪 | B21: 副总经理兼海外气表产品规划管理部及多元智能产品规划管理部产品总监 | C21: 45707 | D21: 星期三 | E21: 工作日 | F21: 08:33 | G21: 正常 | H21: 19:02 | I21: 正常
A22: 何威迪 | B22: 副总经理兼海外气表产品规划管理部及多元智能产品规划管理部产品总监 | C22: 45708 | D22: 星期四 | E22: 工作日 | F22: 08:28 | G22: 正常 | H22: 20:01 | I22: 正常
A23: 何威迪 | B23: 副总经理兼海外气表产品规划管理部及多元智能产品规划管理部产品总监 | C23: 45709 | D23: 星期五 | E23: 工作日 | F23: 08:31 | G23: 正常 | H23: 19:02 | I23: 正常
A24: 何威迪 | B24: 副总经理兼海外气表产品规划管理部及多元智能产品规划管理部产品总监 | C24: 45710 | D24: 星期六 | E24: 休息 | F24: 08:51 | G24: 正常 | H24: 11:27 | I24: 正常
A25: 何威迪 | B25: 副总经理兼海外气表产品规划管理部及多元智能产品规划管理部产品总监 | C25: 45711 | D25: 星期日 | E25: 休息
A26: 何威迪 | B26: 副总经理兼海外气表产品规划管理部及多元智能产品规划管理部产品总监 | C26: 45712 | D26: 星期一 | E26: 工作日 | F26: 08:09 | G26: 正常 | H26: 20:00 | I26: 正常
A27: 何威迪 | B27: 副总经理兼海外气表产品规划管理部及多元智能产品规划管理部产品总监 | C27: 45713 | D27: 星期二 | E27: 工作日 | F27: 08:29 | G27: 正常 | H27: 18:25 | I27: 正常
A28: 何威迪 | B28: 副总经理兼海外气表产品规划管理部及多元智能产品规划管理部产品总监 | C28: 45714 | D28: 星期三 | E28: 工作日 | F28: 08:26 | G28: 正常 | H28: 17:35 | I28: 正常
A29: 何威迪 | B29: 副总经理兼海外气表产品规划管理部及多元智能产品规划管理部产品总监 | C29: 45715 | D29: 星期四 | E29: 工作日 | F29: 08:28 | G29: 正常 | H29: 20:13 | I29: 正常
A30: 何威迪 | B30: 副总经理兼海外气表产品规划管理部及多元智能产品规划管理部产品总监 | C30: 45716 | D30: 星期五 | E30: 工作日 | F30: 08:30 | G30: 正常 | H30: 18:27 | I30: 正常
A31: 李季 | B31: 副总经理兼国内水表产品规划管理部产品总监 | C31: 45689 | D31: 星期六 | E31: 休息
A32: 李季 | B32: 副总经理兼国内水表产品规划管理部产品总监 | C32: 45690 | D32: 星期日 | E32: 休息
A33: 李季 | B33: 副总经理兼国内水表产品规划管理部产品总监 | C33: 45691 | D33: 星期一 | E33: 休息
A34: 李季 | B34: 副总经理兼国内水表产品规划管理部产品总监 | C34: 45692 | D34: 星期二 | E34: 休息
A35: 李季 | B35: 副总经理兼国内水表产品规划管理部产品总监 | C35: 45693 | D35: 星期三 | E35: 工作日 | F35: 07:43 | G35: 正常 | H35: 18:41 | I35: 正常
A36: 李季 | B36: 副总经理兼国内水表产品规划管理部产品总监 | C36: 45694 | D36: 星期四 | E36: 工作日 | F36: 07:37 | G36: 正常 | H36: 20:05 | I36: 正常
A37: 李季 | B37: 副总经理兼国内水表产品规划管理部产品总监 | C37: 45695 | D37: 星期五 | E37: 工作日 | F37: 08:31 | G37: 正常 | H37: 18:49 | I37: 正常
A38: 李季 | B38: 副总经理兼国内水表产品规划管理部产品总监 | C38: 45696 | D38: 星期六 | E38: 工作日 | F38: 07:48 | G38: 正常 | H38: 18:13 | I38: 正常
A39: 李季 | B39: 副总经理兼国内水表产品规划管理部产品总监 | C39: 45697 | D39: 星期日 | E39: 休息
A40: 李季 | B40: 副总经理兼国内水表产品规划管理部产品总监 | C40: 45698 | D40: 星期一 | E40: 工作日 | F40: 07:57 | G40: 正常 | H40: 20:11 | I40: 正常
...

Sheet 餐补次数
A1: 姓名 | B1: 出差次数 （扣除） | C1: 姓名 | D1: 出差次数 | F1: 姓名 | G1: 调休次数 (扣除) | H1: 姓名 | I1: 调休次数 | K1: 姓名 | L1: 迟到次数 | M1: 姓名 | N1: 迟到次数 | P1: 姓名 | Q1: 餐补次数 （增加） | R1: 姓名 | S1: 餐补次数
A2: 李文华 | B2: 1 | C2: {=INDEX(A:A,MIN(IF(COUNTIF(C$1:C1,$A$2:$A$569),2^16,ROW($2:$569))))&""} -> 李文华 | D2: =SUMPRODUCT(($A$2:$A$569=C2)*($B$2:$B$569)) -> 7 | F2: 王扩军 | G2: 0.5 | H2: {=INDEX(F:F,MIN(IF(COUNTIF(H$1:H1,$F$2:$F$569),2^16,ROW($2:$569))))&""} -> 王扩军 | I2: =SUMPRODUCT(($F$2:$F$569=H2)*($G$2:$G$569)) -> 0.5 | M2: {=INDEX(K:K,MIN(IF(COUNTIF(M$1:M1,$K$2:$K$100),2^16,ROW($2:$100))))&""} | N2: =SUMPRODUCT(($K$2:$K$100=M2)*($L$2:$L$100)) -> 0 | P2: 何威迪 | Q2: 1 | R2: {=INDEX(P:P,MIN(IF(COUNTIF(R$1:R1,$P$2:$P$1500),2^16,ROW($2:$1500))))&""} -> 何威迪 | S2: {=SUMPRODUCT(($P$2:$P$1500=R2)*($Q$2:$Q$1500))} -> 8
A3: 李文华 | B3: 1 | C3: {=INDEX(A:A,MIN(IF(COUNTIF(C$1:C2,$A$2:$A$569),2^16,ROW($2:$569))))&""} -> 刘晓峰 | D3: =SUMPRODUCT(($A$2:$A$569=C3)*($B$2:$B$569)) -> 5 | F3: 连成鹏 | G3: 0.5 | H3: {=INDEX(F:F,MIN(IF(COUNTIF(H$1:H2,$F$2:$F$569),2^16,ROW($2:$569))))&""} -> 连成鹏 | I3: =SUMPRODUCT(($F$2:$F$569=H3)*($G$2:$G$569)) -> 1 | M3: {=INDEX(K:K,MIN(IF(COUNTIF(M$1:M2,$K$2:$K$100),2^16,ROW($2:$100))))&""} | N3: =SUMPRODUCT(($K$2:$K$100=M3)*($L$2:$L$100)) -> 0 | P3: 何威迪 | Q3: 1 | R3: {=INDEX(P:P,MIN(IF(COUNTIF(R$1:R2,$P$2:$P$1500),2^16,ROW($2:$1500))))&""} -> 李季 | S3: {=SUMPRODUCT(($P$2:$P$1500=R3)*($Q$2:$Q$1500))} -> 5
A4: 李文华 | B4: 1 | C4: {=INDEX(A:A,MIN(IF(COUNTIF(C$1:C3,$A$2:$A$569),2^16,ROW($2:$569))))&""} -> 戴梦莹 | D4: =SUMPRODUCT(($A$2:$A$569=C4)*($B$2:$B$569)) -> 1 | F4: 连成鹏 | G4: 0.5 | H4: {=INDEX(F:F,MIN(IF(COUNTIF(H$1:H3,$F$2:$F$569),2^16,ROW($2:$569))))&""} -> 张景雲 | I4: =SUMPRODUCT(($F$2:$F$569=H4)*($G$2:$G$569)) -> 1 | M4: {=INDEX(K:K,MIN(IF(COUNTIF(M$1:M3,$K$2:$K$100),2^16,ROW($2:$100))))&""} | N4: =SUMPRODUCT(($K$2:$K$100=M4)*($L$2:$L$100)) -> 0 | P4: 何威迪 | Q4: 1 | R4: {=INDEX(P:P,MIN(IF(COUNTIF(R$1:R3,$P$2:$P$1500),2^16,ROW($2:$1500))))&""} -> 李文华 | S4: {=SUMPRODUCT(($P$2:$P$1500=R4)*($Q$2:$Q$1500))} -> 5
A5: 李文华 | B5: 1 | C5: {=INDEX(A:A,MIN(IF(COUNTIF(C$1:C4,$A$2:$A$569),2^16,ROW($2:$569))))&""} -> 连成鹏 | D5: =SUMPRODUCT(($A$2:$A$569=C5)*($B$2:$B$569)) -> 4 | F5: 张景雲 | G5: 1 | H5: {=INDEX(F:F,MIN(IF(COUNTIF(H$1:H4,$F$2:$F$569),2^16,ROW($2:$569))))&""} -> 曹超 | I5: =SUMPRODUCT(($F$2:$F$569=H5)*($G$2:$G$569)) -> 1 | M5: {=INDEX(K:K,MIN(IF(COUNTIF(M$1:M4,$K$2:$K$100),2^16,ROW($2:$100))))&""} | N5: =SUMPRODUCT(($K$2:$K$100=M5)*($L$2:$L$100)) -> 0 | P5: 何威迪 | Q5: 1 | R5: {=INDEX(P:P,MIN(IF(COUNTIF(R$1:R4,$P$2:$P$1500),2^16,ROW($2:$1500))))&""} -> 刘晓峰 | S5: {=SUMPRODUCT(($P$2:$P$1500=R5)*($Q$2:$Q$1500))} -> 6
A6: 李文华 | B6: 1 | C6: {=INDEX(A:A,MIN(IF(COUNTIF(C$1:C5,$A$2:$A$569),2^16,ROW($2:$569))))&""} -> 廖勇江 | D6: =SUMPRODUCT(($A$2:$A$569=C6)*($B$2:$B$569)) -> 2 | F6: 曹超 | G6: 1 | H6: {=INDEX(F:F,MIN(IF(COUNTIF(H$1:H5,$F$2:$F$569),2^16,ROW($2:$569))))&""} -> 黄杨蕊 | I6: =SUMPRODUCT(($F$2:$F$569=H6)*($G$2:$G$569)) -> 2 | M6: {=INDEX(K:K,MIN(IF(COUNTIF(M$1:M5,$K$2:$K$100),2^16,ROW($2:$100))))&""} | N6: =SUMPRODUCT(($K$2:$K$100=M6)*($L$2:$L$100)) -> 0 | P6: 何威迪 | Q6: 1 | R6: {=INDEX(P:P,MIN(IF(COUNTIF(R$1:R5,$P$2:$P$1500),2^16,ROW($2:$1500))))&""} -> 王扩军 | S6: {=SUMPRODUCT(($P$2:$P$1500=R6)*($Q$2:$Q$1500))} -> 7.5
A7: 李文华 | B7: 1 | C7: {=INDEX(A:A,MIN(IF(COUNTIF(C$1:C6,$A$2:$A$569),2^16,ROW($2:$569))))&""} -> 刘青 | D7: =SUMPRODUCT(($A$2:$A$569=C7)*($B$2:$B$569)) -> 1 | F7: 黄杨蕊 | G7: 1 | H7: {=INDEX(F:F,MIN(IF(COUNTIF(H$1:H6,$F$2:$F$569),2^16,ROW($2:$569))))&""} -> 李芳 | I7: =SUMPRODUCT(($F$2:$F$569=H7)*($G$2:$G$569)) -> 0.5 | M7: {=INDEX(K:K,MIN(IF(COUNTIF(M$1:M6,$K$2:$K$100),2^16,ROW($2:$100))))&""} | N7: =SUMPRODUCT(($K$2:$K$100=M7)*($L$2:$L$100)) -> 0 | P7: 何威迪 | Q7: 1 | R7: {=INDEX(P:P,MIN(IF(COUNTIF(R$1:R6,$P$2:$P$1500),2^16,ROW($2:$1500))))&""} -> 戴梦莹 | S7: {=SUMPRODUCT(($P$2:$P$1500=R7)*($Q$2:$Q$1500))} -> 6
A8: 李文华 | B8: 1 | C8: {=INDEX(A:A,MIN(IF(COUNTIF(C$1:C7,$A$2:$A$569),2^16,ROW($2:$569))))&""} -> 杨善平 | D8: =SUMPRODUCT(($A$2:$A$569=C8)*($B$2:$B$569)) -> 2 | F8: 黄杨蕊 | G8: 1 | H8: {=INDEX(F:F,MIN(IF(COUNTIF(H$1:H7,$F$2:$F$569),2^16,ROW($2:$569))))&""} -> 李旭 | I8: =SUMPRODUCT(($F$2:$F$569=H8)*($G$2:$G$569)) -> 1 | M8: {=INDEX(K:K,MIN(IF(COUNTIF(M$1:M7,$K$2:$K$100),2^16,ROW($2:$100))))&""} | N8: =SUMPRODUCT(($K$2:$K$100=M8)*($L$2:$L$100)) -> 0 | P8: 何威迪 | Q8: 1 | R8: {=INDEX(P:P,MIN(IF(COUNTIF(R$1:R7,$P$2:$P$1500),2^16,ROW($2:$1500))))&""} -> 楼晓丽 | S8: {=SUMPRODUCT(($P$2:$P$1500=R8)*($Q$2:$Q$1500))} -> 2
A9: 刘晓峰 | B9: 1 | C9: {=INDEX(A:A,MIN(IF(COUNTIF(C$1:C8,$A$2:$A$569),2^16,ROW($2:$569))))&""} -> 冯瀚 | D9: =SUMPRODUCT(($A$2:$A$569=C9)*($B$2:$B$569)) -> 1 | F9: 李芳 | G9: 0.5 | H9: {=INDEX(F:F,MIN(IF(COUNTIF(H$1:H8,$F$2:$F$569),2^16,ROW($2:$569))))&""} -> 秦文近 | I9: =SUMPRODUCT(($F$2:$F$569=H9)*($G$2:$G$569)) -> 5 | M9: {=INDEX(K:K,MIN(IF(COUNTIF(M$1:M8,$K$2:$K$100),2^16,ROW($2:$100))))&""} | N9: =SUMPRODUCT(($K$2:$K$100=M9)*($L$2:$L$100)) -> 0 | P9: 何威迪 | Q9: 1 | R9: {=INDEX(P:P,MIN(IF(COUNTIF(R$1:R8,$P$2:$P$1500),2^16,ROW($2:$1500))))&""} -> 郭海桃 | S9: {=SUMPRODUCT(($P$2:$P$1500=R9)*($Q$2:$Q$1500))} -> 7
A10: 刘晓峰 | B10: 1 | C10: {=INDEX(A:A,MIN(IF(COUNTIF(C$1:C9,$A$2:$A$569),2^16,ROW($2:$569))))&""} -> 金永利 | D10: =SUMPRODUCT(($A$2:$A$569=C10)*($B$2:$B$569)) -> 1 | F10: 李旭 | G10: 1 | H10: {=INDEX(F:F,MIN(IF(COUNTIF(H$1:H9,$F$2:$F$569),2^16,ROW($2:$569))))&""} -> 吴鑫卓 | I10: =SUMPRODUCT(($F$2:$F$569=H10)*($G$2:$G$569)) -> 3 | M10: {=INDEX(K:K,MIN(IF(COUNTIF(M$1:M9,$K$2:$K$100),2^16,ROW($2:$100))))&""} | N10: =SUMPRODUCT(($K$2:$K$100=M10)*($L$2:$L$100)) -> 0 | P10: 李季 | Q10: 1 | R10: {=INDEX(P:P,MIN(IF(COUNTIF(R$1:R9,$P$2:$P$1500),2^16,ROW($2:$1500))))&""} -> 林贤顺 | S10: {=SUMPRODUCT(($P$2:$P$1500=R10)*($Q$2:$Q$1500))} -> 6
A11: 刘晓峰 | B11: 1 | C11: {=INDEX(A:A,MIN(IF(COUNTIF(C$1:C10,$A$2:$A$569),2^16,ROW($2:$569))))&""} -> 杨卉卉 | D11: =SUMPRODUCT(($A$2:$A$569=C11)*($B$2:$B$569)) -> 1 | F11: 秦文近 | G11: 1 | H11: {=INDEX(F:F,MIN(IF(COUNTIF(H$1:H10,$F$2:$F$569),2^16,ROW($2:$569))))&""} -> 杨坤 | I11: =SUMPRODUCT(($F$2:$F$569=H11)*($G$2:$G$569)) -> 0.5 | M11: {=INDEX(K:K,MIN(IF(COUNTIF(M$1:M10,$K$2:$K$100),2^16,ROW($2:$100))))&""} | N11: =SUMPRODUCT(($K$2:$K$100=M11)*($L$2:$L$100)) -> 0 | P11: 李季 | Q11: 1 | R11: {=INDEX(P:P,MIN(IF(COUNTIF(R$1:R10,$P$2:$P$1500),2^16,ROW($2:$1500))))&""} -> 李雪霁 | S11: {=SUMPRODUCT(($P$2:$P$1500=R11)*($Q$2:$Q$1500))} -> 1
A12: 刘晓峰 | B12: 1 | C12: {=INDEX(A:A,MIN(IF(COUNTIF(C$1:C11,$A$2:$A$569),2^16,ROW($2:$569))))&""} -> 丁哲伟 | D12: =SUMPRODUCT(($A$2:$A$569=C12)*($B$2:$B$569)) -> 2 | F12: 秦文近 | G12: 1 | H12: {=INDEX(F:F,MIN(IF(COUNTIF(H$1:H11,$F$2:$F$569),2^16,ROW($2:$569))))&""} -> 杨雨晨 | I12: =SUMPRODUCT(($F$2:$F$569=H12)*($G$2:$G$569)) -> 1 | M12: {=INDEX(K:K,MIN(IF(COUNTIF(M$1:M11,$K$2:$K$100),2^16,ROW($2:$100))))&""} | N12: =SUMPRODUCT(($K$2:$K$100=M12)*($L$2:$L$100)) -> 0 | P12: 李季 | Q12: 1 | R12: {=INDEX(P:P,MIN(IF(COUNTIF(R$1:R11,$P$2:$P$1500),2^16,ROW($2:$1500))))&""} -> 宋佳慧 | S12: {=SUMPRODUCT(($P$2:$P$1500=R12)*($Q$2:$Q$1500))} -> 6
A13: 刘晓峰 | B13: 1 | C13: {=INDEX(A:A,MIN(IF(COUNTIF(C$1:C12,$A$2:$A$569),2^16,ROW($2:$569))))&""} -> 朱万胜 | D13: =SUMPRODUCT(($A$2:$A$569=C13)*($B$2:$B$569)) -> 5 | F13: 秦文近 | G13: 1 | H13: {=INDEX(F:F,MIN(IF(COUNTIF(H$1:H12,$F$2:$F$569),2^16,ROW($2:$569))))&""} -> 周逸轩 | I13: =SUMPRODUCT(($F$2:$F$569=H13)*($G$2:$G$569)) -> 0.5 | M13: {=INDEX(K:K,MIN(IF(COUNTIF(M$1:M12,$K$2:$K$100),2^16,ROW($2:$100))))&""} | N13: =SUMPRODUCT(($K$2:$K$100=M13)*($L$2:$L$100)) -> 0 | P13: 李季 | Q13: 1 | R13: {=INDEX(P:P,MIN(IF(COUNTIF(R$1:R12,$P$2:$P$1500),2^16,ROW($2:$1500))))&""} -> 连成鹏 | S13: {=SUMPRODUCT(($P$2:$P$1500=R13)*($Q$2:$Q$1500))} -> 5
... A17: 连成鹏 | B17: 1 | C17: {=INDEX(A:A,MIN(IF(COUNTIF(C$1:C16,$A$2:$A$569),2^16,ROW($2:$569))))&""} -> 王兵 | D17: =SUMPRODUCT(($A$2:$A$569=C17)*($B$2:$B$569)) -> 1 | F17: 吴鑫卓 | G17: 0.5 | H17: {=INDEX(F:F,MIN(IF(COUNTIF(H$1:H16,$F$2:$F$569),2^16,ROW($2:$569))))&""} -> 张燕 | I17: =SUMPRODUCT(($F$2:$F$569=H17)*($G$2:$G$569)) -> 2 | M17: {=INDEX(K:K,MIN(IF(COUNTIF(M$1:M16,$K$2:$K$100),2^16,ROW($2:$100))))&""} | N17: =SUMPRODUCT(($K$2:$K$100=M17)*($L$2:$L$100)) -> 0 | P17: 李文华 | Q17: 1 | R17: {=INDEX(P:P,MIN(IF(COUNTIF(R$1:R16,$P$2:$P$1500),2^16,ROW($2:$1500))))&""} -> 曹超 | S17: {=SUMPRODUCT(($P$2:$P$1500=R17)*($Q$2:$Q$1500))} -> 8
A18: 连成鹏 | B18: 1 | C18: {=INDEX(A:A,MIN(IF(COUNTIF(C$1:C17,$A$2:$A$569),2^16,ROW($2:$569))))&""} | F18: 吴鑫卓 | G18: 0.5 | H18: {=INDEX(F:F,MIN(IF(COUNTIF(H$1:H17,$F$2:$F$569),2^16,ROW($2:$569))))&""} -> 干然草 | I18: =SUMPRODUCT(($F$2:$F$569=H18)*($G$2:$G$569)) -> 1 | M18: {=INDEX(K:K,MIN(IF(COUNTIF(M$1:M17,$K$2:$K$100),2^16,ROW($2:$100))))&""} | N18: =SUMPRODUCT(($K$2:$K$100=M18)*($L$2:$L$100)) -> 0 | P18: 李文华 | Q18: 1 | R18: {=INDEX(P:P,MIN(IF(COUNTIF(R$1:R17,$P$2:$P$1500),2^16,ROW($2:$1500))))&""} -> 陈远发 | S18: {=SUMPRODUCT(($P$2:$P$1500=R18)*($Q$2:$Q$1500))} -> 8
A19: 廖勇江 | B19: 1 | C19: {=INDEX(A:A,MIN(IF(COUNTIF(C$1:C18,$A$2:$A$569),2^16,ROW($2:$569))))&""} | F19: 吴鑫卓 | G19: 0.5 | H19: {=INDEX(F:F,MIN(IF(COUNTIF(H$1:H18,$F$2:$F$569),2^16,ROW($2:$569))))&""} -> 李林翰 | I19: =SUMPRODUCT(($F$2:$F$569=H19)*($G$2:$G$569)) -> 1 | M19: {=INDEX(K:K,MIN(IF(COUNTIF(M$1:M18,$K$2:$K$100),2^16,ROW($2:$100))))&""} | N19: =SUMPRODUCT(($K$2:$K$100=M19)*($L$2:$L$100)) -> 0 | P19: 李文华 | Q19: 1 | R19: {=INDEX(P:P,MIN(IF(COUNTIF(R$1:R18,$P$2:$P$1500),2^16,ROW($2:$1500))))&""} -> 黄杨蕊 | S19: {=SUMPRODUCT(($P$2:$P$1500=R19)*($Q$2:$Q$1500))} -> 6
A20: 廖勇江 | B20: 1 | C20: {=INDEX(A:A,MIN(IF(COUNTIF(C$1:C19,$A$2:$A$569),2^16,ROW($2:$569))))&""} | F20: 吴鑫卓 | G20: 0.5 | H20: {=INDEX(F:F,MIN(IF(COUNTIF(H$1:H19,$F$2:$F$569),2^16,ROW($2:$569))))&""} -> 陈斌 | I20: =SUMPRODUCT(($F$2:$F$569=H20)*($G$2:$G$569)) -> 2 | M20: {=INDEX(K:K,MIN(IF(COUNTIF(M$1:M19,$K$2:$K$100),2^16,ROW($2:$100))))&""} | N20: =SUMPRODUCT(($K$2:$K$100=M20)*($L$2:$L$100)) -> 0 | P20: 刘晓峰 | Q20: 1 | R20: {=INDEX(P:P,MIN(IF(COUNTIF(R$1:R19,$P$2:$P$1500),2^16,ROW($2:$1500))))&""} -> 李芳 | S20: {=SUMPRODUCT(($P$2:$P$1500=R20)*($Q$2:$Q$1500))} -> 9
A21: 刘青 | B21: 1 | C21: {=INDEX(A:A,MIN(IF(COUNTIF(C$1:C20,$A$2:$A$569),2^16,ROW($2:$569))))&""} | F21: 杨坤 | G21: 0.5 | H21: {=INDEX(F:F,MIN(IF(COUNTIF(H$1:H20,$F$2:$F$569),2^16,ROW($2:$569))))&""} -> 陈为泽 | I21: =SUMPRODUCT(($F$2:$F$569=H21)*($G$2:$G$569)) -> 0.5 | M21: {=INDEX(K:K,MIN(IF(COUNTIF(M$1:M20,$K$2:$K$100),2^16,ROW($2:$100))))&""} | N21: =SUMPRODUCT(($K$2:$K$100=M21)*($L$2:$L$100)) -> 0 | P21: 刘晓峰 | Q21: 1 | R21: {=INDEX(P:P,MIN(IF(COUNTIF(R$1:R20,$P$2:$P$1500),2^16,ROW($2:$1500))))&""} -> 李旭 | S21: {=SUMPRODUCT(($P$2:$P$1500=R21)*($Q$2:$Q$1500))} -> 10.5
A22: 杨善平 | B22: 1 | C22: {=INDEX(A:A,MIN(IF(COUNTIF(C$1:C21,$A$2:$A$569),2^16,ROW($2:$569))))&""} | F22: 杨雨晨 | G22: 1 | H22: {=INDEX(F:F,MIN(IF(COUNTIF(H$1:H21,$F$2:$F$569),2^16,ROW($2:$569))))&""} -> 夏雨捷 | I22: =SUMPRODUCT(($F$2:$F$569=H22)*($G$2:$G$569)) -> 1 | M22: {=INDEX(K:K,MIN(IF(COUNTIF(M$1:M21,$K$2:$K$100),2^16,ROW($2:$100))))&""} | N22: =SUMPRODUCT(($K$2:$K$100=M22)*($L$2:$L$100)) -> 0 | P22: 刘晓峰 | Q22: 1 | R22: {=INDEX(P:P,MIN(IF(COUNTIF(R$1:R21,$P$2:$P$1500),2^16,ROW($2:$1500))))&""} -> 陆巧玲 | S22: {=SUMPRODUCT(($P$2:$P$1500=R22)*($Q$2:$Q$1500))} -> 7
A23: 杨善平 | B23: 1 | C23: {=INDEX(A:A,MIN(IF(COUNTIF(C$1:C22,$A$2:$A$569),2^16,ROW($2:$569))))&""} | F23: 周逸轩 | G23: 0.5 | H23: {=INDEX(F:F,MIN(IF(COUNTIF(H$1:H22,$F$2:$F$569),2^16,ROW($2:$569))))&""} -> 杨善平 | I23: =SUMPRODUCT(($F$2:$F$569=H23)*($G$2:$G$569)) -> 2 | M23: {=INDEX(K:K,MIN(IF(COUNTIF(M$1:M22,$K$2:$K$100),2^16,ROW($2:$100))))&""} | N23: =SUMPRODUCT(($K$2:$K$100=M23)*($L$2:$L$100)) -> 0 | P23: 刘晓峰 | Q23: 1 | R23: {=INDEX(P:P,MIN(IF(COUNTIF(R$1:R22,$P$2:$P$1500),2^16,ROW($2:$1500))))&""} -> 秦文近 | S23: {=SUMPRODUCT(($P$2:$P$1500=R23)*($Q$2:$Q$1500))} -> 5.5
A24: 冯瀚 | B24: 1 | C24: {=INDEX(A:A,MIN(IF(COUNTIF(C$1:C23,$A$2:$A$569),2^16,ROW($2:$569))))&""} | F24: 孙伟 | G24: 0.5 | H24: {=INDEX(F:F,MIN(IF(COUNTIF(H$1:H23,$F$2:$F$569),2^16,ROW($2:$569))))&""} -> 林杨杨 | I24: =SUMPRODUCT(($F$2:$F$569=H24)*($G$2:$G$569)) -> 1 | M24: {=INDEX(K:K,MIN(IF(COUNTIF(M$1:M23,$K$2:$K$100),2^16,ROW($2:$100))))&""} | N24: =SUMPRODUCT(($K$2:$K$100=M24)*($L$2:$L$100)) -> 0 | P24: 刘晓峰 | Q24: 1 | R24: {=INDEX(P:P,MIN(IF(COUNTIF(R$1:R23,$P$2:$P$1500),2^16,ROW($2:$1500))))&""} -> 王银军 | S24: {=SUMPRODUCT(($P$2:$P$1500=R24)*($Q$2:$Q$1500))} -> 7
A25: 金永利 | B25: 1 | C25: {=INDEX(A:A,MIN(IF(COUNTIF(C$1:C24,$A$2:$A$569),2^16,ROW($2:$569))))&""} | F25: 翁宋兵 | G25: 0.5 | H25: {=INDEX(F:F,MIN(IF(COUNTIF(H$1:H24,$F$2:$F$569),2^16,ROW($2:$569))))&""} -> 旷世麟 | I25: =SUMPRODUCT(($F$2:$F$569=H25)*($G$2:$G$569)) -> 1 | M25: {=INDEX(K:K,MIN(IF(COUNTIF(M$1:M24,$K$2:$K$100),2^16,ROW($2:$100))))&""} | N25: =SUMPRODUCT(($K$2:$K$100=M25)*($L$2:$L$100)) -> 0 | P25: 刘晓峰 | Q25: 1 | R25: {=INDEX(P:P,MIN(IF(COUNTIF(R$1:R24,$P$2:$P$1500),2^16,ROW($2:$1500))))&""} -> 吴鑫卓 | S25: {=SUMPRODUCT(($P$2:$P$1500=R25)*($Q$2:$Q$1500))} -> 9
A26: 杨卉卉 | B26: 1 | C26: {=INDEX(A:A,MIN(IF(COUNTIF(C$1:C25,$A$2:$A$56),2^16,ROW($2:$56))))&""} | F26: 陈林 | G26: 0.5 | H26: {=INDEX(F:F,MIN(IF(COUNTIF(H$1:H25,$F$2:$F$569),2^16,ROW($2:$569))))&""} -> 赵继宝 | I26: =SUMPRODUCT(($F$2:$F$569=H26)*($G$2:$G$569)) -> 1 | M26: {=INDEX(K:K,MIN(IF(COUNTIF(M$1:M25,$K$2:$K$100),2^16,ROW($2:$100))))&""} | N26: =SUMPRODUCT(($K$2:$K$100=M26)*($L$2:$L$100)) -> 0 | P26: 王扩军 | Q26: 1 | R26: {=INDEX(P:P,MIN(IF(COUNTIF(R$1:R25,$P$2:$P$1500),2^16,ROW($2:$1500))))&""} -> 杨坤 | S26: {=SUMPRODUCT(($P$2:$P$1500=R26)*($Q$2:$Q$1500))} -> 9
A27: 丁哲伟 | B27: 1 | C27: {=INDEX(A:A,MIN(IF(COUNTIF(C$1:C26,$A$2:$A$56),2^16,ROW($2:$56))))&""} | F27: 张燕 | G27: 1 | H27: {=INDEX(F:F,MIN(IF(COUNTIF(H$1:H26,$F$2:$F$569),2^16,ROW($2:$569))))&""} -> 冯瀚 | I27: =SUMPRODUCT(($F$2:$F$569=H27)*($G$2:$G$569)) -> 0.5 | M27: {=INDEX(K:K,MIN(IF(COUNTIF(M$1:M26,$K$2:$K$100),2^16,ROW($2:$100))))&""} | N27: =SUMPRODUCT(($K$2:$K$100=M27)*($L$2:$L$100)) -> 0 | P27: 王扩军 | Q27: 1 | R27: {=INDEX(P:P,MIN(IF(COUNTIF(R$1:R26,$P$2:$P$1500),2^16,ROW($2:$1500))))&""} -> 杨雨晨 | S27: {=SUMPRODUCT(($P$2:$P$1500=R27)*($Q$2:$Q$1500))} -> 7
A28: 丁哲伟 | B28: 1 | C28: {=INDEX(A:A,MIN(IF(COUNTIF(C$1:C27,$A$2:$A$56),2^16,ROW($2:$56))))&""} | F28: 张燕 | G28: 1 | H28: {=INDEX(F:F,MIN(IF(COUNTIF(H$1:H27,$F$2:$F$569),2^16,ROW($2:$569))))&""} -> 黄驰洋 | I28: =SUMPRODUCT(($F$2:$F$569=H28)*($G$2:$G$569)) -> 2 | M28: {=INDEX(K:K,MIN(IF(COUNTIF(M$1:M27,$K$2:$K$100),2^16,ROW($2:$100))))&""} | N28: =SUMPRODUCT(($K$2:$K$100=M28)*($L$2:$L$100)) -> 0 | P28: 王扩军 | Q28: 1 | R28: {=INDEX(P:P,MIN(IF(COUNTIF(R$1:R27,$P$2:$P$1500),2^16,ROW($2:$1500))))&""} -> 余乐 | S28: {=SUMPRODUCT(($P$2:$P$1500=R28)*($Q$2:$Q$1500))} -> 7
A29: 朱万胜 | B29: 1 | C29: {=INDEX(A:A,MIN(IF(COUNTIF(C$1:C28,$A$2:$A$56),2^16,ROW($2:$56))))&""} | F29: 干然草 | G29: 1 | H29: {=INDEX(F:F,MIN(IF(COUNTIF(H$1:H28,$F$2:$F$569),2^16,ROW($2:$569))))&""} -> 马振斌 | I29: =SUMPRODUCT(($F$2:$F$569=H29)*($G$2:$G$569)) -> 1 | M29: {=INDEX(K:K,MIN(IF(COUNTIF(M$1:M28,$K$2:$K$100),2^16,ROW($2:$100))))&""} | N29: =SUMPRODUCT(($K$2:$K$100=M29)*($L$2:$L$100)) -> 0 | P29: 王扩军 | Q29: 1 | R29: {=INDEX(P:P,MIN(IF(COUNTIF(R$1:R28,$P$2:$P$1500),2^16,ROW($2:$1500))))&""} -> 张培强 | S29: {=SUMPRODUCT(($P$2:$P$1500=R29)*($Q$2:$Q$1500))} -> 6
A30: 朱万胜 | B30: 1 | C30: {=INDEX(A:A,MIN(IF(COUNTIF(C$1:C29,$A$2:$A$56),2^16,ROW($2:$56))))&""} | F30: 李林翰 | G30: 1 | H30: {=INDEX(F:F,MIN(IF(COUNTIF(H$1:H29,$F$2:$F$569),2^16,ROW($2:$569))))&""} -> 时慧玲 | I30: =SUMPRODUCT(($F$2:$F$569=H30)*($G$2:$G$569)) -> 1 | M30: {=INDEX(K:K,MIN(IF(COUNTIF(M$1:M29,$K$2:$K$100),2^16,ROW($2:$100))))&""} | N30: =SUMPRODUCT(($K$2:$K$100=M30)*($L$2:$L$100)) -> 0 | P30: 王扩军 | Q30: 1 | R30: {=INDEX(P:P,MIN(IF(COUNTIF(R$1:R29,$P$2:$P$1500),2^16,ROW($2:$1500))))&""} -> 张欠欠 | S30: {=SUMPRODUCT(($P$2:$P$1500=R30)*($Q$2:$Q$1500))} -> 4
A31: 朱万胜 | B31: 1 | C31: {=INDEX(A:A,MIN(IF(COUNTIF(C$1:C30,$A$2:$A$56),2^16,ROW($2:$56))))&""} | F31: 陈斌 | G31: 1 | H31: {=INDEX(F:F,MIN(IF(COUNTIF(H$1:H30,$F$2:$F$569),2^16,ROW($2:$569))))&""} -> 魏雪 | I31: =SUMPRODUCT(($F$2:$F$569=H31)*($G$2:$G$569)) -> 1 | M31: {=INDEX(K:K,MIN(IF(COUNTIF(M$1:M30,$K$2:$K$100),2^16,ROW($2:$100))))&""} | N31: =SUMPRODUCT(($K$2:$K$100=M31)*($L$2:$L$100)) -> 0 | P31: 王扩军 | Q31: 0.5 | R31: {=INDEX(P:P,MIN(IF(COUNTIF(R$1:R30,$P$2:$P$1500),2^16,ROW($2:$1500))))&""} -> 周逸轩 | S31: {=SUMPRODUCT(($P$2:$P$1500=R31)*($Q$2:$Q$1500))} -> 7.5
A32: 朱万胜 | B32: 1 | C32: {=INDEX(A:A,MIN(IF(COUNTIF(C$1:C31,$A$2:$A$56),2^16,ROW($2:$56))))&""} | F32: 陈斌 | G32: 1 | H32: {=INDEX(F:F,MIN(IF(COUNTIF(H$1:H31,$F$2:$F$569),2^16,ROW($2:$569))))&""} -> 习津涛 | I32: =SUMPRODUCT(($F$2:$F$569=H32)*($G$2:$G$569)) -> 1.5 | M32: {=INDEX(K:K,MIN(IF(COUNTIF(M$1:M31,$K$2:$K$100),2^16,ROW($2:$100))))&""} | N32: =SUMPRODUCT(($K$2:$K$100=M32)*($L$2:$L$100)) -> 0 | P32: 王扩军 | Q32: 1 | R32: {=INDEX(P:P,MIN(IF(COUNTIF(R$1:R31,$P$2:$P$1500),2^16,ROW($2:$1500))))&""} -> 孙伟 | S32: {=SUMPRODUCT(($P$2:$P$1500=R32)*($Q$2:$Q$1500))} -> 7
A33: 朱万胜 | B33: 1 | C33: {=INDEX(A:A,MIN(IF(COUNTIF(C$1:C32,$A$2:$A$56),2^16,ROW($2:$56))))&""} | F33: 陈为泽 | G33: 0.5 | H33: {=INDEX(F:F,MIN(IF(COUNTIF(H$1:H32,$F$2:$F$569),2^16,ROW($2:$569))))&""} -> 赵磊 | I33: =SUMPRODUCT(($F$2:$F$569=H33)*($G$2:$G$569)) -> 4 | M33: {=INDEX(K:K,MIN(IF(COUNTIF(M$1:M32,$K$2:$K$100),2^16,ROW($2:$100))))&""} | N33: =SUMPRODUCT(($K$2:$K$100=M33)*($L$2:$L$100)) -> 0 | P33: 王扩军 | Q33: 1 | R33: {=INDEX(P:P,MIN(IF(COUNTIF(R$1:R32,$P$2:$P$1500),2^16,ROW($2:$1500))))&""} -> 翁宋兵 | S33: {=SUMPRODUCT(($P$2:$P$1500=R33)*($Q$2:$Q$1500))} -> 3
A34: 刘帅 | B34: 1 | C34: {=INDEX(A:A,MIN(IF(COUNTIF(C$1:C33,$A$2:$A$56),2^16,ROW($2:$56))))&""} | F34: 夏雨捷 | G34: 1 | H34: {=INDEX(F:F,MIN(IF(COUNTIF(H$1:H33,$F$2:$F$569),2^16,ROW($2:$569))))&""} -> 朱亚垒 | I34: =SUMPRODUCT(($F$2:$F$569=H34)*($G$2:$G$569)) -> 2 | M34: {=INDEX(K:K,MIN(IF(COUNTIF(M$1:M33,$K$2:$K$100),2^16,ROW($2:$100))))&""} | N34: =SUMPRODUCT(($K$2:$K$100=M34)*($L$2:$L$100)) -> 0 | P34: 戴梦莹 | Q34: 1 | R34: {=INDEX(P:P,MIN(IF(COUNTIF(R$1:R33,$P$2:$P$1500),2^16,ROW($2:$1500))))&""} -> 陈林 | S34: {=SUMPRODUCT(($P$2:$P$1500=R34)*($Q$2:$Q$1500))} -> 7
A35: 徐晋 | B35: 1 | C35: {=INDEX(A:A,MIN(IF(COUNTIF(C$1:C34,$A$2:$A$56),2^16,ROW($2:$56))))&""} | F35: 杨善平 | G35: 1 | H35: {=INDEX(F:F,MIN(IF(COUNTIF(H$1:H34,$F$2:$F$569),2^16,ROW($2:$569))))&""} -> 林彬俊 | I35: =SUMPRODUCT(($F$2:$F$569=H35)*($G$2:$G$569)) -> 0.5 | M35: {=INDEX(K:K,MIN(IF(COUNTIF(M$1:M34,$K$2:$K$100),2^16,ROW($2:$100))))&""} | N35: =SUMPRODUCT(($K$2:$K$100=M35)*($L$2:$L$100)) -> 0 | P35: 戴梦莹 | Q35: 1 | R35: {=INDEX(P:P,MIN(IF(COUNTIF(R$1:R34,$P$2:$P$1500),2^16,ROW($2:$1500))))&""} -> 孟栋成 | S35: {=SUMPRODUCT(($P$2:$P$1500=R35)*($Q$2:$Q$1500))} -> 7
A36: 徐晋 | B36: 1 | C36: {=INDEX(A:A,MIN(IF(COUNTIF(C$1:C35,$A$2:$A$56),2^16,ROW($2:$56))))&""} | F36: 杨善平 | G36: 1 | H36: {=INDEX(F:F,MIN(IF(COUNTIF(H$1:H35,$F$2:$F$569),2^16,ROW($2:$569))))&""} -> 吕鹏 | I36: =SUMPRODUCT(($F$2:$F$569=H36)*($G$2:$G$569)) -> 3 | M36: {=INDEX(K:K,MIN(IF(COUNTIF(M$1:M35,$K$2:$K$100),2^16,ROW($2:$100))))&""} | N36: =SUMPRODUCT(($K$2:$K$100=M36)*($L$2:$L$100)) -> 0 | P36: 戴梦莹 | Q36: 1 | R36: {=INDEX(P:P,MIN(IF(COUNTIF(R$1:R35,$P$2:$P$1500),2^16,ROW($2:$1500))))&""} -> 全卓栋 | S36: {=SUMPRODUCT(($P$2:$P$1500=R36)*($Q$2:$Q$1500))} -> 7
A37: 徐晋 | B37: 1 | C37: {=INDEX(A:A,MIN(IF(COUNTIF(C$1:C36,$A$2:$A$56),2^16,ROW($2:$56))))&""} | F37: 林杨杨 | G37: 1 | H37: {=INDEX(F:F,MIN(IF(COUNTIF(H$1:H36,$F$2:$F$569),2^16,ROW($2:$569))))&""} -> 吕许 | I37: =SUMPRODUCT(($F$2:$F$569=H37)*($G$2:$G$569)) -> 1 | M37: {=INDEX(K:K,MIN(IF(COUNTIF(M$1:M36,$K$2:$K$100),2^16,ROW($2:$100))))&""} | N37: =SUMPRODUCT(($K$2:$K$100=M37)*($L$2:$L$100)) -> 0 | P37: 戴梦莹 | Q37: 1 | R37: {=INDEX(P:P,MIN(IF(COUNTIF(R$1:R36,$P$2:$P$1500),2^16,ROW($2:$1500))))&""} -> 盛俊昆 | S37: {=SUMPRODUCT(($P$2:$P$1500=R37)*($Q$2:$Q$1500))} -> 6
... A42: 王兵 | B42: 1 | C42: {=INDEX(A:A,MIN(IF(COUNTIF(C$1:C41,$A$2:$A$56),2^16,ROW($2:$56))))&""} | F42: 黄驰洋 | G42: 0.5 | H42: {=INDEX(F:F,MIN(IF(COUNTIF(H$1:H41,$F$2:$F$569),2^16,ROW($2:$569))))&""} -> 叶先意 | I42: =SUMPRODUCT(($F$2:$F$569=H42)*($G$2:$G$569)) -> 0.5 | M42: {=INDEX(K:K,MIN(IF(COUNTIF(M$1:M41,$K$2:$K$100),2^16,ROW($2:$100))))&""} | N42: =SUMPRODUCT(($K$2:$K$100=M42)*($L$2:$L$100)) -> 0 | P42: 郭海桃 | Q42: 1 | R42: {=INDEX(P:P,MIN(IF(COUNTIF(R$1:R41,$P$2:$P$1500),2^16,ROW($2:$1500))))&""} -> 廖勇江 | S42: {=SUMPRODUCT(($P$2:$P$1500=R42)*($Q$2:$Q$1500))} -> 15
C43: {=INDEX(A:A,MIN(IF(COUNTIF(C$1:C42,$A$2:$A$56),2^16,ROW($2:$56))))&""} | F43: 黄驰洋 | G43: 0.5 | H43: {=INDEX(F:F,MIN(IF(COUNTIF(H$1:H42,$F$2:$F$569),2^16,ROW($2:$569))))&""} -> 刘帅 | I43: =SUMPRODUCT(($F$2:$F$569=H43)*($G$2:$G$569)) -> 4 | M43: {=INDEX(K:K,MIN(IF(COUNTIF(M$1:M42,$K$2:$K$100),2^16,ROW($2:$100))))&""} | N43: =SUMPRODUCT(($K$2:$K$100=M43)*($L$2:$L$100)) -> 0 | P43: 郭海桃 | Q43: 1 | R43: {=INDEX(P:P,MIN(IF(COUNTIF(R$1:R42,$P$2:$P$1500),2^16,ROW($2:$1500))))&""} -> 楚旭 | S43: {=SUMPRODUCT(($P$2:$P$1500=R43)*($Q$2:$Q$1500))} -> 6
C44: {=INDEX(A:A,MIN(IF(COUNTIF(C$1:C43,$A$2:$A$56),2^16,ROW($2:$56))))&""} | F44: 黄驰洋 | G44: 0.5 | H44: {=INDEX(F:F,MIN(IF(COUNTIF(H$1:H43,$F$2:$F$569),2^16,ROW($2:$569))))&""} -> 邹美洋 | I44: =SUMPRODUCT(($F$2:$F$569=H44)*($G$2:$G$569)) -> 2 | M44: {=INDEX(K:K,MIN(IF(COUNTIF(M$1:M43,$K$2:$K$100),2^16,ROW($2:$100))))&""} | N44: =SUMPRODUCT(($K$2:$K$100=M44)*($L$2:$L$100)) -> 0 | P44: 郭海桃 | Q44: 1 | R44: {=INDEX(P:P,MIN(IF(COUNTIF(R$1:R43,$P$2:$P$1500),2^16,ROW($2:$1500))))&""} -> 干然草 | S44: {=SUMPRODUCT(($P$2:$P$1500=R44)*($Q$2:$Q$1500))} -> 6
C45: {=INDEX(A:A,MIN(IF(COUNTIF(C$1:C44,$A$2:$A$56),2^16,ROW($2:$56))))&""} | F45: 马振斌 | G45: 1 | H45: {=INDEX(F:F,MIN(IF(COUNTIF(H$1:H44,$F$2:$F$569),2^16,ROW($2:$569))))&""} -> 刘高杰 | I45: =SUMPRODUCT(($F$2:$F$569=H45)*($G$2:$G$569)) -> 1 | M45: {=INDEX(K:K,MIN(IF(COUNTIF(M$1:M44,$K$2:$K$100),2^16,ROW($2:$100))))&""} | N45: =SUMPRODUCT(($K$2:$K$100=M45)*($L$2:$L$100)) -> 0 | P45: 郭海桃 | Q45: 1 | R45: {=INDEX(P:P,MIN(IF(COUNTIF(R$1:R44,$P$2:$P$1500),2^16,ROW($2:$1500))))&""} -> 李林翰 | S45: {=SUMPRODUCT(($P$2:$P$1500=R45)*($Q$2:$Q$1500))} -> 6
C46: {=INDEX(A:A,MIN(IF(COUNTIF(C$1:C45,$A$2:$A$56),2^16,ROW($2:$56))))&""} | F46: 时慧玲 | G46: 1 | H46: {=INDEX(F:F,MIN(IF(COUNTIF(H$1:H45,$F$2:$F$569),2^16,ROW($2:$569))))&""} -> 潘凌云 | I46: =SUMPRODUCT(($F$2:$F$569=H46)*($G$2:$G$569)) -> 1.5 | M46: {=INDEX(K:K,MIN(IF(COUNTIF(M$1:M45,$K$2:$K$100),2^16,ROW($2:$100))))&""} | N46: =SUMPRODUCT(($K$2:$K$100=M46)*($L$2:$L$100)) -> 0 | P46: 郭海桃 | Q46: 1 | R46: {=INDEX(P:P,MIN(IF(COUNTIF(R$1:R45,$P$2:$P$1500),2^16,ROW($2:$1500))))&""} -> 刘丽 | S46: {=SUMPRODUCT(($P$2:$P$1500=R46)*($Q$2:$Q$1500))} -> 8
C47: {=INDEX(A:A,MIN(IF(COUNTIF(C$1:C46,$A$2:$A$56),2^16,ROW($2:$56))))&""} | F47: 魏雪 | G47: 1 | H47: {=INDEX(F:F,MIN(IF(COUNTIF(H$1:H46,$F$2:$F$569),2^16,ROW($2:$569))))&""} -> 王晓雅 | I47: =SUMPRODUCT(($F$2:$F$569=H47)*($G$2:$G$569)) -> 2 | M47: {=INDEX(K:K,MIN(IF(COUNTIF(M$1:M46,$K$2:$K$100),2^16,ROW($2:$100))))&""} | N47: =SUMPRODUCT(($K$2:$K$100=M47)*($L$2:$L$100)) -> 0 | P47: 郭海桃 | Q47: 1 | R47: {=INDEX(P:P,MIN(IF(COUNTIF(R$1:R46,$P$2:$P$1500),2^16,ROW($2:$1500))))&""} -> 王鹏飞 | S47: {=SUMPRODUCT(($P$2:$P$1500=R47)*($Q$2:$Q$1500))} -> 11
...

Sheet 出勤汇总
A1: 员工编号 | B1: 部门 | C1: 姓名 | D1: 岗位 | E1: 月份 | F1: 迟到次数 | G1: 事假(天) | H1: 病假(天) | I1: 产假(天) | J1: 婚假(天) | K1: 丧假(天) | L1: 护理假(天) | M1: 其他假(天) | N1: 请假总天数 | O1: 平时计费加班工时 | P1: 周末计费加班工时 | Q1: 节假日计费加班工时 | R1: 翻倍后计费加班工时 | S1: 应上班(天) | T1: 上班(天) | U1: 正常餐补 | V1: 餐补调整 | W1: 当月餐补 | X1: 年份 | Y1: 账套 | Z1: 餐补扣除 | AA1: 出差(天) | AB1: 调休/居家(天) | AC1: 实上班(天) | AD1: 餐补调数(天) | AE1: 餐补调整 | AF1: 当月餐补合计
A2: 165619 | B2: 研发中心 | C2: 李文华 | D2: 副总经理兼（国内）膜式气表产品规划管理部及（国内）超声气表产品规划管理部产品总监 | E2: 2月 | N2: =SUM(G2:M2) -> 0 | S2: 19 | T2: =S2-N2 -> 19 | U2: =AC2*15 -> 180 | V2: =AE2-Z2*15 -> 75 | W2: =U2+V2 -> 255 | X2: 2025 | Y2: HR-001 | AA2: =VLOOKUP(C2,餐补次数!$C$2:$D$17,2,0) -> 7 | AC2: =T2-AA2-AB2 -> 12 | AD2: =VLOOKUP(C2,餐补次数!$R$2:$S$150,2,0) -> 5 | AE2: =AD2*15 -> 75 | AF2: =U2+AE2-Z2*15 -> 255
A3: 165620 | B3: 研发中心 | C3: 王兵 | D3: 副总经理 | E3: 2月 | N3: =SUM(G3:M3) -> 0 | S3: 19 | T3: =S3-N3 -> 19 | U3: =AC3*15 -> 255 | V3: =AE3-Z3*15 -> 157.5 | W3: =U3+V3 -> 412.5 | X3: 2025 | Y3: HR-001 | AA3: =VLOOKUP(C3,餐补次数!$C$2:$D$17,2,0) -> 1 | AB3: =VLOOKUP(C3,餐补次数!$H$2:$I$100,2,0) -> 1 | AC3: =T3-AA3-AB3 -> 17 | AD3: =VLOOKUP(C3,餐补次数!$R$2:$S$150,2,0) -> 10.5 | AE3: =AD3*15 -> 157.5 | AF3: =U3+AE3-Z3*15 -> 412.5
A4: 165621 | B4: 研发中心 | C4: 林扬宣 | D4: 副总经理 | E4: 2月 | N4: =SUM(G4:M4) -> 0 | S4: 19 | T4: =S4-N4 -> 19 | U4: =AC4*15 -> 240 | V4: =AE4-Z4*15 -> 150 | W4: =U4+V4 -> 390 | X4: 2025 | Y4: HR-001 | AA4: =VLOOKUP(C4,餐补次数!$C$2:$D$17,2,0) -> 3 | AC4: =T4-AA4-AB4 -> 16 | AD4: =VLOOKUP(C4,餐补次数!$R$2:$S$150,2,0) -> 10 | AE4: =AD4*15 -> 150 | AF4: =U4+AE4-Z4*15 -> 390
A5: 165622 | B5: 研发中心 | C5: 李季 | D5: 副总经理兼国内水表产品规划管理部产品总监 | E5: 2月 | N5: =SUM(G5:M5) -> 0 | S5: 19 | T5: =S5-N5 -> 19 | U5: =AC5*15 -> 285 | V5: =AE5-Z5*15 -> 75 | W5: =U5+V5 -> 360 | X5: 2025 | Y5: HR-001 | AC5: =T5-AA5-AB5 -> 19 | AD5: =VLOOKUP(C5,餐补次数!$R$2:$S$150,2,0) -> 5 | AE5: =AD5*15 -> 75 | AF5: =U5+AE5-Z5*15 -> 360
A6: 165623 | B6: 研发中心 | C6: 王扩军 | D6: 总经理助理 | E6: 2月 | N6: =SUM(G6:M6) -> 0 | S6: 19 | T6: =S6-N6 -> 19 | U6: =AC6*15 -> 277.5 | V6: =AE6-Z6*15 -> 112.5 | W6: =U6+V6 -> 390 | X6: 2025 | Y6: HR-001 | AB6: =VLOOKUP(C6,餐补次数!$H$2:$I$100,2,0) -> 0.5 | AC6: =T6-AA6-AB6 -> 18.5 | AD6: =VLOOKUP(C6,餐补次数!$R$2:$S$150,2,0) -> 7.5 | AE6: =AD6*15 -> 112.5 | AF6: =U6+AE6-Z6*15 -> 390
A7: 165624 | B7: 研发中心 | C7: 何威迪 | D7: 副总经理兼海外气表产品规划管理部及多元智能产品规划管理部产品总监 | E7: 2月 | N7: =SUM(G7:M7) -> 0 | S7: 19 | T7: =S7-N7 -> 19 | U7: =AC7*15 -> 285 | V7: =AE7-Z7*15 -> 120 | W7: =U7+V7 -> 405 | X7: 2025 | Y7: HR-001 | AC7: =T7-AA7-AB7 -> 19 | AD7: =VLOOKUP(C7,餐补次数!$R$2:$S$150,2,0) -> 8 | AE7: =AD7*15 -> 120 | AF7: =U7+AE7-Z7*15 -> 405
A8: 165625 | B8: 研发中心 | C8: 刘晓峰 | D8: 总经理助理兼海外水表产品规划管理部产品总监 | E8: 2月 | N8: =SUM(G8:M8) -> 0 | S8: 19 | T8: =S8-N8 -> 19 | U8: =AC8*15 -> 210 | V8: =AE8-Z8*15 -> 90 | W8: =U8+V8 -> 300 | X8: 2025 | Y8: HR-001 | AA8: =VLOOKUP(C8,餐补次数!$C$2:$D$17,2,0) -> 5 | AC8: =T8-AA8-AB8 -> 14 | AD8: =VLOOKUP(C8,餐补次数!$R$2:$S$150,2,0) -> 6 | AE8: =AD8*15 -> 90 | AF8: =U8+AE8-Z8*15 -> 300
A9: 165643 | B9: 综合管理部（研发） | C9: 郑佳男 | D9: 主管 | E9: 2月 | N9: =SUM(G9:M9) -> 0 | S9: 19 | T9: =S9-N9 -> 19 | U9: =AC9*15 -> 285 | V9: =AE9-Z9*15 -> 150 | W9: =U9+V9 -> 435 | X9: 2025 | Y9: HR-001 | AC9: =T9-AA9-AB9 -> 19 | AD9: =VLOOKUP(C9,餐补次数!$R$2:$S$150,2,0) -> 10 | AE9: =AD9*15 -> 150 | AF9: =U9+AE9-Z9*15 -> 435
A10: 165644 | B10: 产品标准化管理部 | C10: 张燕 | D10: 体系工程师(PLM) | E10: 2月 | M10: 1 | N10: =SUM(G10:M10) -> 1 | S10: 19 | T10: =S10-N10 -> 18 | U10: =AC10*15 -> 240 | V10: =AE10-Z10*15 -> 60 | W10: =U10+V10 -> 300 | X10: 2025 | Y10: HR-001 | AB10: =VLOOKUP(C10,餐补次数!$H$2:$I$100,2,0) -> 2 | AC10: =T10-AA10-AB10 -> 16 | AD10: =VLOOKUP(C10,餐补次数!$R$2:$S$150,2,0) -> 4 | AE10: =AD10*15 -> 60 | AF10: =U10+AE10-Z10*15 -> 300
A11: 165645 | B11: 综合管理部（研发） | C11: 方璐 | D11: 综合事务主管 | E11: 2月 | N11: =SUM(G11:M11) -> 0 | S11: 19 | T11: =S11-N11 -> 19 | U11: =AC11*15 -> 285 | V11: =AE11-Z11*15 -> 0 | W11: =U11+V11 -> 285 | X11: 2025 | Y11: HR-001 | AC11: =T11-AA11-AB11 -> 19 | AD11: 0 | AE11: =AD11*15 -> 0 | AF11: =U11+AE11-Z11*15 -> 285
A12: 165646 | B12: 产品测试部 | C12: 杨坤 | D12: 主管 | E12: 2月 | N12: =SUM(G12:M12) -> 0 | S12: 19 | T12: =S12-N12 -> 19 | U12: =AC12*15 -> 277.5 | V12: =AE12-Z12*15 -> 135 | W12: =U12+V12 -> 412.5 | X12: 2025 | Y12: HR-001 | AB12: =VLOOKUP(C12,餐补次数!$H$2:$I$100,2,0) -> 0.5 | AC12: =T12-AA12-AB12 -> 18.5 | AD12: =VLOOKUP(C12,餐补次数!$R$2:$S$150,2,0) -> 9 | AE12: =AD12*15 -> 135 | AF12: =U12+AE12-Z12*15 -> 412.5
A13: 165647 | B13: 产品测试部 | C13: 陆巧玲 | D13: 部门副经理（主持工作） | E13: 2月 | N13: =SUM(G13:M13) -> 0 | S13: 19 | T13: =S13-N13 -> 19 | U13: =AC13*15 -> 285 | V13: =AE13-Z13*15 -> 105 | W13: =U13+V13 -> 390 | X13: 2025 | Y13: HR-001 | AC13: =T13-AA13-AB13 -> 19 | AD13: =VLOOKUP(C13,餐补次数!$R$2:$S$150,2,0) -> 7 | AE13: =AD13*15 -> 105 | AF13: =U13+AE13-Z13*15 -> 390
A14: 165648 | B14: 产品测试部 | C14: 张欠欠 | D14: 产品测试工程师 | E14: 2月 | N14: =SUM(G14:M14) -> 0 | S14: 19 | T14: =S14-N14 -> 19 | U14: =AC14*15 -> 285 | V14: =AE14-Z14*15 -> 60 | W14: =U14+V14 -> 345 | X14: 2025 | Y14: HR-001 | AC14: =T14-AA14-AB14 -> 19 | AD14: =VLOOKUP(C14,餐补次数!$R$2:$S$150,2,0) -> 4 | AE14: =AD14*15 -> 60 | AF14: =U14+AE14-Z14*15 -> 345
A15: 165649 | B15: 产品测试部 | C15: 李芳 | D15: 产品测试工程师 | E15: 2月 | N15: =SUM(G15:M15) -> 0 | S15: 19 | T15: =S15-N15 -> 19 | U15: =AC15*15 -> 277.5 | V15: =AE15-Z15*15 -> 135 | W15: =U15+V15 -> 412.5 | X15: 2025 | Y15: HR-001 | AB15: =VLOOKUP(C15,餐补次数!$H$2:$I$100,2,0) -> 0.5 | AC15: =T15-AA15-AB15 -> 18.5 | AD15: =VLOOKUP(C15,餐补次数!$R$2:$S$150,2,0) -> 9 | AE15: =AD15*15 -> 135 | AF15: =U15+AE15-Z15*15 -> 412.5
A16: 165650 | B16: 产品测试部 | C16: 曹超 | D16: 测试工程师 | E16: 2月 | N16: =SUM(G16:M16) -> 0 | S16: 19 | T16: =S16-N16 -> 19 | U16: =AC16*15 -> 270 | V16: =AE16-Z16*15 -> 120 | W16: =U16+V16 -> 390 | X16: 2025 | Y16: HR-001 | AB16: =VLOOKUP(C16,餐补次数!$H$2:$I$100,2,0) -> 1 | AC16: =T16-AA16-AB16 -> 18 | AD16: =VLOOKUP(C16,餐补次数!$R$2:$S$150,2,0) -> 8 | AE16: =AD16*15 -> 120 | AF16: =U16+AE16-Z16*15 -> 390
A17: 165652 | B17: 产品测试部 | C17: 黄杨蕊 | D17: 测试工程师 | E17: 2月 | N17: =SUM(G17:M17) -> 0 | S17: 19 | T17: =S17-N17 -> 19 | U17: =AC17*15 -> 255 | V17: =AE17-Z17*15 -> 90 | W17: =U17+V17 -> 345 | X17: 2025 | Y17: HR-001 | AB17: =VLOOKUP(C17,餐补次数!$H$2:$I$100,2,0) -> 2 | AC17: =T17-AA17-AB17 -> 17 | AD17: =VLOOKUP(C17,餐补次数!$R$2:$S$150,2,0) -> 6 | AE17: =AD17*15 -> 90 | AF17: =U17+AE17-Z17*15 -> 345
A18: 165653 | B18: 产品测试部 | C18: 杨雨晨 | D18: 测试工程师 | E18: 2月 | N18: =SUM(G18:M18) -> 0 | S18: 19 | T18: =S18-N18 -> 19 | U18: =AC18*15 -> 270 | V18: =AE18-Z18*15 -> 105 | W18: =U18+V18 -> 375 | X18: 2025 | Y18: HR-001 | AB18: =VLOOKUP(C18,餐补次数!$H$2:$I$100,2,0) -> 1 | AC18: =T18-AA18-AB18 -> 18 | AD18: =VLOOKUP(C18,餐补次数!$R$2:$S$150,2,0) -> 7 | AE18: =AD18*15 -> 105 | AF18: =U18+AE18-Z18*15 -> 375
A19: 165655 | B19: 产品测试部 | C19: 周逸轩 | D19: 测试工程师 | E19: 2月 | N19: =SUM(G19:M19) -> 0 | S19: 19 | T19: =S19-N19 -> 19 | U19: =AC19*15 -> 277.5 | V19: =AE19-Z19*15 -> 112.5 | W19: =U19+V19 -> 390 | X19: 2025 | Y19: HR-001 | AB19: =VLOOKUP(C19,餐补次数!$H$2:$I$100,2,0) -> 0.5 | AC19: =T19-AA19-AB19 -> 18.5 | AD19: =VLOOKUP(C19,餐补次数!$R$2:$S$150,2,0) -> 7.5 | AE19: =AD19*15 -> 112.5 | AF19: =U19+AE19-Z19*15 -> 390
A20: 165656 | B20: 产品测试部 | C20: 陈远发 | D20: 测试工程师 | E20: 2月 | N20: =SUM(G20:M20) -> 0 | S20: 19 | T20: =S20-N20 -> 19 | U20: =AC20*15 -> 285 | V20: =AE20-Z20*15 -> 120 | W20: =U20+V20 -> 405 | X20: 2025 | Y20: HR-001 | AC20: =T20-AA20-AB20 -> 19 | AD20: =VLOOKUP(C20,餐补次数!$R$2:$S$150,2,0) -> 8 | AE20: =AD20*15 -> 120 | AF20: =U20+AE20-Z20*15 -> 405
A21: 165657 | B21: 产品测试部 | C21: 边皖佳 | D21: 测试工程师 | E21: 2月 | N21: =SUM(G21:M21) -> 0 | S21: 19 | T21: =S21-N21 -> 19 | U21: =AC21*15 -> 285 | V21: =AE21-Z21*15 -> 105 | W21: =U21+V21 -> 390 | X21: 2025 | Y21: HR-001 | AC21: =T21-AA21-AB21 -> 19 | AD21: =VLOOKUP(C21,餐补次数!$R$2:$S$150,2,0) -> 7 | AE21: =AD21*15 -> 105 | AF21: =U21+AE21-Z21*15 -> 390
A22: 165658 | B22: 产品测试部 | C22: 张培强 | D22: 测试工程师 | E22: 2月 | N22: =SUM(G22:M22) -> 0 | S22: 19 | T22: =S22-N22 -> 19 | U22: =AC22*15 -> 285 | V22: =AE22-Z22*15 -> 90 | W22: =U22+V22 -> 375 | X22: 2025 | Y22: HR-001 | AC22: =T22-AA22-AB22 -> 19 | AD22: =VLOOKUP(C22,餐补次数!$R$2:$S$150,2,0) -> 6 | AE22: =AD22*15 -> 90 | AF22: =U22+AE22-Z22*15 -> 375
A23: 165659 | B23: 产品测试部 | C23: 李旭 | D23: 测试工程师 | E23: 2月 | N23: =SUM(G23:M23) -> 0 | S23: 19 | T23: =S23-N23 -> 19 | U23: =AC23*15 -> 270 | V23: =AE23-Z23*15 -> 157.5 | W23: =U23+V23 -> 427.5 | X23: 2025 | Y23: HR-001 | AB23: =VLOOKUP(C23,餐补次数!$H$2:$I$100,2,0) -> 1 | AC23: =T23-AA23-AB23 -> 18 | AD23: =VLOOKUP(C23,餐补次数!$R$2:$S$150,2,0) -> 10.5 | AE23: =AD23*15 -> 157.5 | AF23: =U23+AE23-Z23*15 -> 427.5
A24: 165660 | B24: 产品测试部 | C24: 吴鑫卓 | D24: 测试工程师 | E24: 2月 | N24: =SUM(G24:M24) -> 0 | S24: 19 | T24: =S24-N24 -> 19 | U24: =AC24*15 -> 240 | V24: =AE24-Z24*15 -> 135 | W24: =U24+V24 -> 375 | X24: 2025 | Y24: HR-001 | AB24: =VLOOKUP(C24,餐补次数!$H$2:$I$100,2,0) -> 3 | AC24: =T24-AA24-AB24 -> 16 | AD24: =VLOOKUP(C24,餐补次数!$R$2:$S$150,2,0) -> 9 | AE24: =AD24*15 -> 135 | AF24: =U24+AE24-Z24*15 -> 375
A25: 165661 | B25: 产品测试部 | C25: 秦文近 | D25: 测试工程师 | E25: 2月 | N25: =SUM(G25:M25) -> 0 | S25: 19 | T25: =S25-N25 -> 19 | U25: =AC25*15 -> 210 | V25: =AE25-Z25*15 -> 82.5 | W25: =U25+V25 -> 292.5 | X25: 2025 | Y25: HR-001 | AB25: =VLOOKUP(C25,餐补次数!$H$2:$I$100,2,0) -> 5 | AC25: =T25-AA25-AB25 -> 14 | AD25: =VLOOKUP(C25,餐补次数!$R$2:$S$150,2,0) -> 5.5 | AE25: =AD25*15 -> 82.5 | AF25: =U25+AE25-Z25*15 -> 292.5
A26: 165662 | B26: 产品测试部 | C26: 王银军 | D26: 测试工程师 | E26: 2月 | N26: =SUM(G26:M26) -> 0 | S26: 19 | T26: =S26-N26 -> 19 | U26: =AC26*15 -> 285 | V26: =AE26-Z26*15 -> 105 | W26: =U26+V26 -> 390 | X26: 2025 | Y26: HR-001 | AC26: =T26-AA26-AB26 -> 19 | AD26: =VLOOKUP(C26,餐补次数!$R$2:$S$150,2,0) -> 7 | AE26: =AD26*15 -> 105 | AF26: =U26+AE26-Z26*15 -> 390
A27: 165663 | B27: 产品测试部 | C27: 余乐 | D27: 测试工程师 | E27: 2月 | N27: =SUM(G27:M27) -> 0 | S27: 19 | T27: =S27-N27 -> 19 | U27: =AC27*15 -> 285 | V27: =AE27-Z27*15 -> 105 | W27: =U27+V27 -> 390 | X27: 2025 | Y27: HR-001 | AC27: =T27-AA27-AB27 -> 19 | AD27: =VLOOKUP(C27,餐补次数!$R$2:$S$150,2,0) -> 7 | AE27: =AD27*15 -> 105 | AF27: =U27+AE27-Z27*15 -> 390
A28: 165665 | B28: 产品工程部 | C28: 孙伟 | D28: 部门副经理 | E28: 2月 | N28: =SUM(G28:M28) -> 0 | S28: 19 | T28: =S28-N28 -> 19 | U28: =AC28*15 -> 277.5 | V28: =AE28-Z28*15 -> 105 | W28: =U28+V28 -> 382.5 | X28: 2025 | Y28: HR-001 | AB28: =VLOOKUP(C28,餐补次数!$H$2:$I$100,2,0) -> 0.5 | AC28: =T28-AA28-AB28 -> 18.5 | AD28: =VLOOKUP(C28,餐补次数!$R$2:$S$150,2,0) -> 7 | AE28: =AD28*15 -> 105 | AF28: =U28+AE28-Z28*15 -> 382.5
A29: 165666 | B29: 产品工程部 | C29: 翁宋兵 | D29: 运维工程师 | E29: 2月 | N29: =SUM(G29:M29) -> 0 | S29: 19 | T29: =S29-N29 -> 19 | U29: =AC29*15 -> 277.5 | V29: =AE29-Z29*15 -> 45 | W29: =U29+V29 -> 322.5 | X29: 2025 | Y29: HR-001 | AB29: =VLOOKUP(C29,餐补次数!$H$2:$I$100,2,0) -> 0.5 | AC29: =T29-AA29-AB29 -> 18.5 | AD29: =VLOOKUP(C29,餐补次数!$R$2:$S$150,2,0) -> 3 | AE29: =AD29*15 -> 45 | AF29: =U29+AE29-Z29*15 -> 322.5
A30: 165922 | B30: 产品管理部 | C30: 楼晓丽 | D30: 产品经理 | E30: 2月 | N30: =SUM(G30:M30) -> 0 | S30: 19 | T30: =S30-N30 -> 19 | U30: =AC30*15 -> 285 | V30: =AE30-Z30*15 -> 30 | W30: =U30+V30 -> 315 | X30: 2025 | Y30: HR-001 | AC30: =T30-AA30-AB30 -> 19 | AD30: =VLOOKUP(C30,餐补次数!$R$2:$S$150,2,0) -> 2 | AE30: =AD30*15 -> 30 | AF30: =U30+AE30-Z30*15 -> 315
A31: 165923 | B31: 产品管理部 | C31: 戴梦莹 | D31: 主管 | E31: 2月 | N31: =SUM(G31:M31) -> 0 | S31: 19 | T31: =S31-N31 -> 19 | U31: =AC31*15 -> 270 | V31: =AE31-Z31*15 -> 90 | W31: =U31+V31 -> 360 | X31: 2025 | Y31: HR-001 | AA31: =VLOOKUP(C31,餐补次数!$C$2:$D$17,2,0) -> 1 | AC31: =T31-AA31-AB31 -> 18 | AD31: =VLOOKUP(C31,餐补次数!$R$2:$S$150,2,0) -> 6 | AE31: =AD31*15 -> 90 | AF31: =U31+AE31-Z31*15 -> 360
A32: 165924 | B32: 产品管理部 | C32: 孙倩 | D32: 产品专员 | E32: 2月 | N32: =SUM(G32:M32) -> 0 | S32: 19 | T32: =S32-N32 -> 19 | U32: =AC32*15 -> 285 | V32: =AE32-Z32*15 -> 105 | W32: =U32+V32 -> 390 | X32: 2025 | Y32: HR-001 | AC32: =T32-AA32-AB32 -> 19 | AD32: =VLOOKUP(C32,餐补次数!$R$2:$S$150,2,0) -> 7 | AE32: =AD32*15 -> 105 | AF32: =U32+AE32-Z32*15 -> 390
A33: 165925 | B33: 产品管理部 | C33: 张景雲 | D33: 产品专员 | E33: 2月 | N33: =SUM(G33:M33) -> 0 | S33: 19 | T33: =S33-N33 -> 19 | U33: =AC33*15 -> 270 | V33: =AE33-Z33*15 -> 105 | W33: =U33+V33 -> 375 | X33: 2025 | Y33: HR-001 | AB33: =VLOOKUP(C33,餐补次数!$H$2:$I$100,2,0) -> 1 | AC33: =T33-AA33-AB33 -> 18 | AD33: =VLOOKUP(C33,餐补次数!$R$2:$S$150,2,0) -> 7 | AE33: =AD33*15 -> 105 | AF33: =U33+AE33-Z33*15 -> 375
A34: 166256 | B34: 项目管理部 | C34: 王鹏飞 | D34: 项目经理 | E34: 2月 | N34: =SUM(G34:M34) -> 0 | S34: 19 | T34: =S34-N34 -> 19 | U34: =AC34*15 -> 285 | V34: =AE34-Z34*15 -> 165 | W34: =U34+V34 -> 450 | X34: 2025 | Y34: HR-001 | AC34: =T34-AA34-AB34 -> 19 | AD34: =VLOOKUP(C34,餐补次数!$R$2:$S$150,2,0) -> 11 | AE34: =AD34*15 -> 165 | AF34: =U34+AE34-Z34*15 -> 450
A35: 166257 | B35: 项目管理部 | C35: 楚旭 | D35: 体系工程师 | E35: 2月 | N35: =SUM(G35:M35) -> 0 | S35: 19 | T35: =S35-N35 -> 19 | U35: =AC35*15 -> 285 | V35: =AE35-Z35*15 -> 90 | W35: =U35+V35 -> 375 | X35: 2025 | Y35: HR-001 | AC35: =T35-AA35-AB35 -> 19 | AD35: =VLOOKUP(C35,餐补次数!$R$2:$S$150,2,0) -> 6 | AE35: =AD35*15 -> 90 | AF35: =U35+AE35-Z35*15 -> 375
A36: 166258 | B36: 项目管理部 | C36: 干然草 | D36: 项目经理 | E36: 2月 | N36: =SUM(G36:M36) -> 0 | S36: 19 | T36: =S36-N36 -> 19 | U36: =AC36*15 -> 270 | V36: =AE36-Z36*15 -> 90 | W36: =U36+V36 -> 360 | X36: 2025 | Y36: HR-001 | AB36: =VLOOKUP(C36,餐补次数!$H$2:$I$100,2,0) -> 1 | AC36: =T36-AA36-AB36 -> 18 | AD36: =VLOOKUP(C36,餐补次数!$R$2:$S$150,2,0) -> 6 | AE36: =AD36*15 -> 90 | AF36: =U36+AE36-Z36*15 -> 360
A37: 166259 | B37: 项目管理部 | C37: 刘丽 | D37: 项目经理 | E37: 2月 | N37: =SUM(G37:M37) -> 0 | S37: 19 | T37: =S37-N37 -> 19 | U37: =AC37*15 -> 285 | V37: =AE37-Z37*15 -> 120 | W37: =U37+V37 -> 405 | X37: 2025 | Y37: HR-001 | AC37: =T37-AA37-AB37 -> 19 | AD37: =VLOOKUP(C37,餐补次数!$R$2:$S$150,2,0) -> 8 | AE37: =AD37*15 -> 120 | AF37: =U37+AE37-Z37*15 -> 405
A38: 166260 | B38: 项目管理部 | C38: 李林翰 | D38: 项目助理 | E38: 2月 | N38: =SUM(G38:M38) -> 0 | S38: 19 | T38: =S38-N38 -> 19 | U38: =AC38*15 -> 270 | V38: =AE38-Z38*15 -> 90 | W38: =U38+V38 -> 360 | X38: 2025 | Y38: HR-001 | AB38: =VLOOKUP(C38,餐补次数!$H$2:$I$100,2,0) -> 1 | AC38: =T38-AA38-AB38 -> 18 | AD38: =VLOOKUP(C38,餐补次数!$R$2:$S$150,2,0) -> 6 | AE38: =AD38*15 -> 90 | AF38: =U38+AE38-Z38*15 -> 360
A39: 166444 | B39: 水表技术研究部 | C39: 赵继宝 | D39: 嵌入式软件工程师 | E39: 2月 | N39: =SUM(G39:M39) -> 0 | S39: 19 | T39: =S39-N39 -> 19 | U39: =AC39*15 -> 270 | V39: =AE39-Z39*15 -> 180 | W39: =U39+V39 -> 450 | X39: 2025 | Y39: HR-001 | AB39: =VLOOKUP(C39,餐补次数!$H$2:$I$100,2,0) -> 1 | AC39: =T39-AA39-AB39 -> 18 | AD39: =VLOOKUP(C39,餐补次数!$R$2:$S$150,2,0) -> 12 | AE39: =AD39*15 -> 180 | AF39: =U39+AE39-Z39*15 -> 450
A40: 166445 | B40: 水表技术研究部 | C40: 崔康 | D40: 结构设计工程师 | E40: 2月 | N40: =SUM(G40:M40) -> 0 | S40: 19 | T40: =S40-N40 -> 19 | U40: =AC40*15 -> 285 | V40: =AE40-Z40*15 -> 120 | W40: =U40+V40 -> 405 | X40: 2025 | Y40: HR-001 | AC40: =T40-AA40-AB40 -> 19 | AD40: =VLOOKUP(C40,餐补次数!$R$2:$S$150,2,0) -> 8 | AE40: =AD40*15 -> 120 | AF40: =U40+AE40-Z40*15 -> 405
...

Sheet 打印版
A1: 2月考勤汇总表（研发中心）
A2: 部门 | B2: 姓名 | C2: 岗位 | D2: 月份 | E2: 事假 | F2: 病假 | G2: 产假 | H2: 婚假 | I2: 丧假 | J2: 护理假 | K2: 其他假 | L2: 请假总天数 | M2: 出差 | N2: 调休/居家 | O2: 应上班 | P2: 实上班 | Q2: 餐补调整数 | R2: 餐补调整
A3: 研发中心 | B3: 李文华 | C3: 副总经理 | D3: 2月 | L3: =出勤汇总!N2 -> 0 | M3: =VLOOKUP(B3,出勤汇总!C:AA,25,0) -> 7 | O3: =VLOOKUP(B3,出勤汇总!C:S,17,0) -> 19 | P3: =O3-L3-M3-N3 -> 12 | Q3: =VLOOKUP(B3,餐补次数!R:S,2,0) -> 5 | R3: =Q3*15 -> 75
A4: 研发中心 | B4: 王兵 | C4: 副总经理 | D4: 2月 | M4: =VLOOKUP(B4,出勤汇总!C:AA,25,0) -> 1 | N4: =VLOOKUP(B4,出勤汇总!C:AB,26,0) -> 1 | O4: =VLOOKUP(B4,出勤汇总!C:S,17,0) -> 19 | P4: =O4-L4-M4-N4 -> 17 | Q4: =VLOOKUP(B4,餐补次数!R:S,2,0) -> 10.5 | R4: =Q4*15 -> 157.5
A5: 研发中心 | B5: 林扬宣 | C5: 副总经理 | D5: 2月 | M5: =VLOOKUP(B5,出勤汇总!C:AA,25,0) -> 3 | O5: =VLOOKUP(B5,出勤汇总!C:S,17,0) -> 19 | P5: =O5-L5-M5-N5 -> 16 | Q5: =VLOOKUP(B5,餐补次数!R:S,2,0) -> 10 | R5: =Q5*15 -> 150
A6: 研发中心 | B6: 李季 | C6: 副总经理 | D6: 2月 | O6: =VLOOKUP(B6,出勤汇总!C:S,17,0) -> 19 | P6: =O6-L6-M6-N6 -> 19 | Q6: =VLOOKUP(B6,餐补次数!R:S,2,0) -> 5 | R6: =Q6*15 -> 75
A7: 研发中心 | B7: 王扩军 | C7: 总经理助理 | D7: 2月 | N7: =VLOOKUP(B7,出勤汇总!C:AB,26,0) -> 0.5 | O7: =VLOOKUP(B7,出勤汇总!C:S,17,0) -> 19 | P7: =O7-L7-M7-N7 -> 18.5 | Q7: =VLOOKUP(B7,餐补次数!R:S,2,0) -> 7.5 | R7: =Q7*15 -> 112.5
A8: 研发中心 | B8: 何威迪 | C8: 副总经理 | D8: 2月 | O8: =VLOOKUP(B8,出勤汇总!C:S,17,0) -> 19 | P8: =O8-L8-M8-N8 -> 19 | Q8: =VLOOKUP(B8,餐补次数!R:S,2,0) -> 8 | R8: =Q8*15 -> 120
A9: 研发中心 | B9: 刘晓峰 | C9: 总经理助理 | D9: 2月 | M9: =VLOOKUP(B9,出勤汇总!C:AA,25,0) -> 5 | O9: =VLOOKUP(B9,出勤汇总!C:S,17,0) -> 19 | P9: =O9-L9-M9-N9 -> 14 | Q9: =VLOOKUP(B9,餐补次数!R:S,2,0) -> 6 | R9: =Q9*15 -> 90
A10: 综合管理部（研发） | B10: 郑佳男 | C10: 主管 | D10: 2月 | O10: =VLOOKUP(B10,出勤汇总!C:S,17,0) -> 19 | P10: =O10-L10-M10-N10 -> 19 | Q10: =VLOOKUP(B10,餐补次数!R:S,2,0) -> 10 | R10: =Q10*15 -> 150
A11: 产品标准化管理部 | B11: 张燕 | C11: 体系工程师(PLM) | D11: 2月 | K11: 1 | L11: =出勤汇总!N10 -> 1 | N11: =VLOOKUP(B11,出勤汇总!C:AB,26,0) -> 2 | O11: =VLOOKUP(B11,出勤汇总!C:S,17,0) -> 19 | P11: =O11-L11-M11-N11 -> 16 | Q11: =VLOOKUP(B11,餐补次数!R:S,2,0) -> 4 | R11: =Q11*15 -> 60
A12: 综合管理部（研发） | B12: 方璐 | C12: 综合事务主管 | D12: 2月 | O12: =VLOOKUP(B12,出勤汇总!C:S,17,0) -> 19 | P12: =O12-L12-M12-N12 -> 19 | Q12: 0 | R12: =Q12*15 -> 0
A13: 产品测试部 | B13: 杨坤 | C13: 主管 | D13: 2月 | N13: =VLOOKUP(B13,出勤汇总!C:AB,26,0) -> 0.5 | O13: =VLOOKUP(B13,出勤汇总!C:S,17,0) -> 19 | P13: =O13-L13-M13-N13 -> 18.5 | Q13: =VLOOKUP(B13,餐补次数!R:S,2,0) -> 9 | R13: =Q13*15 -> 135
A14: 产品测试部 | B14: 陆巧玲 | C14: 部门副经理（主持工作） | D14: 2月 | O14: =VLOOKUP(B14,出勤汇总!C:S,17,0) -> 19 | P14: =O14-L14-M14-N14 -> 19 | Q14: =VLOOKUP(B14,餐补次数!R:S,2,0) -> 7 | R14: =Q14*15 -> 105
A15: 产品测试部 | B15: 张欠欠 | C15: 产品测试工程师 | D15: 2月 | O15: =VLOOKUP(B15,出勤汇总!C:S,17,0) -> 19 | P15: =O15-L15-M15-N15 -> 19 | Q15: =VLOOKUP(B15,餐补次数!R:S,2,0) -> 4 | R15: =Q15*15 -> 60
A16: 产品测试部 | B16: 李芳 | C16: 产品测试工程师 | D16: 2月 | N16: =VLOOKUP(B16,出勤汇总!C:AB,26,0) -> 0.5 | O16: =VLOOKUP(B16,出勤汇总!C:S,17,0) -> 19 | P16: =O16-L16-M16-N16 -> 18.5 | Q16: =VLOOKUP(B16,餐补次数!R:S,2,0) -> 9 | R16: =Q16*15 -> 135
A17: 产品测试部 | B17: 曹超 | C17: 测试工程师 | D17: 2月 | N17: =VLOOKUP(B17,出勤汇总!C:AB,26,0) -> 1 | O17: =VLOOKUP(B17,出勤汇总!C:S,17,0) -> 19 | P17: =O17-L17-M17-N17 -> 18 | Q17: =VLOOKUP(B17,餐补次数!R:S,2,0) -> 8 | R17: =Q17*15 -> 120
A18: 产品测试部 | B18: 黄杨蕊 | C18: 测试工程师 | D18: 2月 | N18: =VLOOKUP(B18,出勤汇总!C:AB,26,0) -> 2 | O18: =VLOOKUP(B18,出勤汇总!C:S,17,0) -> 19 | P18: =O18-L18-M18-N18 -> 17 | Q18: =VLOOKUP(B18,餐补次数!R:S,2,0) -> 6 | R18: =Q18*15 -> 90
A19: 产品测试部 | B19: 杨雨晨 | C19: 测试工程师 | D19: 2月 | N19: =VLOOKUP(B19,出勤汇总!C:AB,26,0) -> 1 | O19: =VLOOKUP(B19,出勤汇总!C:S,17,0) -> 19 | P19: =O19-L19-M19-N19 -> 18 | Q19: =VLOOKUP(B19,餐补次数!R:S,2,0) -> 7 | R19: =Q19*15 -> 105
A20: 产品测试部 | B20: 周逸轩 | C20: 测试工程师 | D20: 2月 | N20: =VLOOKUP(B20,出勤汇总!C:AB,26,0) -> 0.5 | O20: =VLOOKUP(B20,出勤汇总!C:S,17,0) -> 19 | P20: =O20-L20-M20-N20 -> 18.5 | Q20: =VLOOKUP(B20,餐补次数!R:S,2,0) -> 7.5 | R20: =Q20*15 -> 112.5
A21: 产品测试部 | B21: 陈远发 | C21: 测试工程师 | D21: 2月 | O21: =VLOOKUP(B21,出勤汇总!C:S,17,0) -> 19 | P21: =O21-L21-M21-N21 -> 19 | Q21: =VLOOKUP(B21,餐补次数!R:S,2,0) -> 8 | R21: =Q21*15 -> 120
A22: 产品测试部 | B22: 边皖佳 | C22: 测试工程师 | D22: 2月 | O22: =VLOOKUP(B22,出勤汇总!C:S,17,0) -> 19 | P22: =O22-L22-M22-N22 -> 19 | Q22: =VLOOKUP(B22,餐补次数!R:S,2,0) -> 7 | R22: =Q22*15 -> 105
A23: 产品测试部 | B23: 张培强 | C23: 测试工程师 | D23: 2月 | O23: =VLOOKUP(B23,出勤汇总!C:S,17,0) -> 19 | P23: =O23-L23-M23-N23 -> 19 | Q23: =VLOOKUP(B23,餐补次数!R:S,2,0) -> 6 | R23: =Q23*15 -> 90
A24: 产品测试部 | B24: 李旭 | C24: 测试工程师 | D24: 2月 | N24: =VLOOKUP(B24,出勤汇总!C:AB,26,0) -> 1 | O24: =VLOOKUP(B24,出勤汇总!C:S,17,0) -> 19 | P24: =O24-L24-M24-N24 -> 18 | Q24: =VLOOKUP(B24,餐补次数!R:S,2,0) -> 10.5 | R24: =Q24*15 -> 157.5
A25: 产品测试部 | B25: 吴鑫卓 | C25: 测试工程师 | D25: 2月 | N25: =VLOOKUP(B25,出勤汇总!C:AB,26,0) -> 3 | O25: =VLOOKUP(B25,出勤汇总!C:S,17,0) -> 19 | P25: =O25-L25-M25-N25 -> 16 | Q25: =VLOOKUP(B25,餐补次数!R:S,2,0) -> 9 | R25: =Q25*15 -> 135
A26: 产品测试部 | B26: 秦文近 | C26: 测试工程师 | D26: 2月 | N26: =VLOOKUP(B26,出勤汇总!C:AB,26,0) -> 5 | O26: =VLOOKUP(B26,出勤汇总!C:S,17,0) -> 19 | P26: =O26-L26-M26-N26 -> 14 | Q26: =VLOOKUP(B26,餐补次数!R:S,2,0) -> 5.5 | R26: =Q26*15 -> 82.5
A27: 产品测试部 | B27: 王银军 | C27: 测试工程师 | D27: 2月 | O27: =VLOOKUP(B27,出勤汇总!C:S,17,0) -> 19 | P27: =O27-L27-M27-N27 -> 19 | Q27: =VLOOKUP(B27,餐补次数!R:S,2,0) -> 7 | R27: =Q27*15 -> 105
A28: 产品测试部 | B28: 余乐 | C28: 测试工程师 | D28: 2月 | O28: =VLOOKUP(B28,出勤汇总!C:S,17,0) -> 19 | P28: =O28-L28-M28-N28 -> 19 | Q28: =VLOOKUP(B28,餐补次数!R:S,2,0) -> 7 | R28: =Q28*15 -> 105
A29: 产品工程部 | B29: 孙伟 | C29: 部门副经理 | D29: 2月 | N29: =VLOOKUP(B29,出勤汇总!C:AB,26,0) -> 0.5 | O29: =VLOOKUP(B29,出勤汇总!C:S,17,0) -> 19 | P29: =O29-L29-M29-N29 -> 18.5 | Q29: =VLOOKUP(B29,餐补次数!R:S,2,0) -> 7 | R29: =Q29*15 -> 105
A30: 产品工程部 | B30: 翁宋兵 | C30: 运维工程师 | D30: 2月 | N30: =VLOOKUP(B30,出勤汇总!C:AB,26,0) -> 0.5 | O30: =VLOOKUP(B30,出勤汇总!C:S,17,0) -> 19 | P30: =O30-L30-M30-N30 -> 18.5 | Q30: =VLOOKUP(B30,餐补次数!R:S,2,0) -> 3 | R30: =Q30*15 -> 45
A31: 产品管理部 | B31: 楼晓丽 | C31: 产品经理 | D31: 2月 | O31: =VLOOKUP(B31,出勤汇总!C:S,17,0) -> 19 | P31: =O31-L31-M31-N31 -> 19 | Q31: =VLOOKUP(B31,餐补次数!R:S,2,0) -> 2 | R31: =Q31*15 -> 30
A32: 产品管理部 | B32: 戴梦莹 | C32: 主管 | D32: 2月 | M32: =VLOOKUP(B32,出勤汇总!C:AA,25,0) -> 1 | O32: =VLOOKUP(B32,出勤汇总!C:S,17,0) -> 19 | P32: =O32-L32-M32-N32 -> 18 | Q32: =VLOOKUP(B32,餐补次数!R:S,2,0) -> 6 | R32: =Q32*15 -> 90
A33: 产品管理部 | B33: 孙倩 | C33: 产品专员 | D33: 2月 | O33: =VLOOKUP(B33,出勤汇总!C:S,17,0) -> 19 | P33: =O33-L33-M33-N33 -> 19 | Q33: =VLOOKUP(B33,餐补次数!R:S,2,0) -> 7 | R33: =Q33*15 -> 105
A34: 产品管理部 | B34: 张景雲 | C34: 产品专员 | D34: 2月 | N34: =VLOOKUP(B34,出勤汇总!C:AB,26,0) -> 1 | O34: =VLOOKUP(B34,出勤汇总!C:S,17,0) -> 19 | P34: =O34-L34-M34-N34 -> 18 | Q34: =VLOOKUP(B34,餐补次数!R:S,2,0) -> 7 | R34: =Q34*15 -> 105
A35: 项目管理部 | B35: 王鹏飞 | C35: 项目经理 | D35: 2月 | O35: =VLOOKUP(B35,出勤汇总!C:S,17,0) -> 19 | P35: =O35-L35-M35-N35 -> 19 | Q35: =VLOOKUP(B35,餐补次数!R:S,2,0) -> 11 | R35: =Q35*15 -> 165
A36: 项目管理部 | B36: 楚旭 | C36: 体系工程师 | D36: 2月 | O36: =VLOOKUP(B36,出勤汇总!C:S,17,0) -> 19 | P36: =O36-L36-M36-N36 -> 19 | Q36: =VLOOKUP(B36,餐补次数!R:S,2,0) -> 6 | R36: =Q36*15 -> 90
A37: 项目管理部 | B37: 干然草 | C37: 项目经理 | D37: 2月 | N37: =VLOOKUP(B37,出勤汇总!C:AB,26,0) -> 1 | O37: =VLOOKUP(B37,出勤汇总!C:S,17,0) -> 19 | P37: =O37-L37-M37-N37 -> 18 | Q37: =VLOOKUP(B37,餐补次数!R:S,2,0) -> 6 | R37: =Q37*15 -> 90
A38: 项目管理部 | B38: 刘丽 | C38: 项目经理 | D38: 2月 | O38: =VLOOKUP(B38,出勤汇总!C:S,17,0) -> 19 | P38: =O38-L38-M38-N38 -> 19 | Q38: =VLOOKUP(B38,餐补次数!R:S,2,0) -> 8 | R38: =Q38*15 -> 120
A39: 项目管理部 | B39: 李林翰 | C39: 项目助理 | D39: 2月 | N39: =VLOOKUP(B39,出勤汇总!C:AB,26,0) -> 1 | O39: =VLOOKUP(B39,出勤汇总!C:S,17,0) -> 19 | P39: =O39-L39-M39-N39 -> 18 | Q39: =VLOOKUP(B39,餐补次数!R:S,2,0) -> 6 | R39: =Q39*15 -> 90
A40: 水表技术研究部 | B40: 赵继宝 | C40: 嵌入式软件工程师 | D40: 2月 | N40: =VLOOKUP(B40,出勤汇总!C:AB,26,0) -> 1 | O40: =VLOOKUP(B40,出勤汇总!C:S,17,0) -> 19 | P40: =O40-L40-M40-N40 -> 18 | Q40: =VLOOKUP(B40,餐补次数!R:S,2,0) -> 12 | R40: =Q40*15 -> 180
...
